{
 "cells": [
  {
   "cell_type": "code",
   "execution_count": 2,
   "metadata": {},
   "outputs": [
    {
     "name": "stderr",
     "output_type": "stream",
     "text": [
      "/usr/local/lib/python2.7/dist-packages/scipy/linalg/basic.py:17: RuntimeWarning: numpy.dtype size changed, may indicate binary incompatibility. Expected 96, got 88\n",
      "  from ._solve_toeplitz import levinson\n",
      "/usr/local/lib/python2.7/dist-packages/scipy/linalg/__init__.py:207: RuntimeWarning: numpy.dtype size changed, may indicate binary incompatibility. Expected 96, got 88\n",
      "  from ._decomp_update import *\n",
      "/usr/local/lib/python2.7/dist-packages/scipy/special/__init__.py:640: RuntimeWarning: numpy.dtype size changed, may indicate binary incompatibility. Expected 96, got 88\n",
      "  from ._ufuncs import *\n",
      "/usr/local/lib/python2.7/dist-packages/scipy/special/_ellip_harm.py:7: RuntimeWarning: numpy.dtype size changed, may indicate binary incompatibility. Expected 96, got 88\n",
      "  from ._ellip_harm_2 import _ellipsoid, _ellipsoid_norm\n",
      "/usr/local/lib/python2.7/dist-packages/scipy/interpolate/_bsplines.py:10: RuntimeWarning: numpy.dtype size changed, may indicate binary incompatibility. Expected 96, got 88\n",
      "  from . import _bspl\n",
      "/usr/local/lib/python2.7/dist-packages/scipy/sparse/lil.py:19: RuntimeWarning: numpy.dtype size changed, may indicate binary incompatibility. Expected 96, got 88\n",
      "  from . import _csparsetools\n",
      "/usr/local/lib/python2.7/dist-packages/scipy/sparse/csgraph/__init__.py:165: RuntimeWarning: numpy.dtype size changed, may indicate binary incompatibility. Expected 96, got 88\n",
      "  from ._shortest_path import shortest_path, floyd_warshall, dijkstra,\\\n",
      "/usr/local/lib/python2.7/dist-packages/scipy/sparse/csgraph/_validation.py:5: RuntimeWarning: numpy.dtype size changed, may indicate binary incompatibility. Expected 96, got 88\n",
      "  from ._tools import csgraph_to_dense, csgraph_from_dense,\\\n",
      "/usr/local/lib/python2.7/dist-packages/scipy/sparse/csgraph/__init__.py:167: RuntimeWarning: numpy.dtype size changed, may indicate binary incompatibility. Expected 96, got 88\n",
      "  from ._traversal import breadth_first_order, depth_first_order, \\\n",
      "/usr/local/lib/python2.7/dist-packages/scipy/sparse/csgraph/__init__.py:169: RuntimeWarning: numpy.dtype size changed, may indicate binary incompatibility. Expected 96, got 88\n",
      "  from ._min_spanning_tree import minimum_spanning_tree\n",
      "/usr/local/lib/python2.7/dist-packages/scipy/sparse/csgraph/__init__.py:170: RuntimeWarning: numpy.dtype size changed, may indicate binary incompatibility. Expected 96, got 88\n",
      "  from ._reordering import reverse_cuthill_mckee, maximum_bipartite_matching, \\\n",
      "/usr/local/lib/python2.7/dist-packages/scipy/spatial/__init__.py:95: RuntimeWarning: numpy.dtype size changed, may indicate binary incompatibility. Expected 96, got 88\n",
      "  from .ckdtree import *\n",
      "/usr/local/lib/python2.7/dist-packages/scipy/spatial/__init__.py:96: RuntimeWarning: numpy.dtype size changed, may indicate binary incompatibility. Expected 96, got 88\n",
      "  from .qhull import *\n",
      "/usr/local/lib/python2.7/dist-packages/scipy/spatial/_spherical_voronoi.py:18: RuntimeWarning: numpy.dtype size changed, may indicate binary incompatibility. Expected 96, got 88\n",
      "  from . import _voronoi\n",
      "/usr/local/lib/python2.7/dist-packages/scipy/spatial/distance.py:122: RuntimeWarning: numpy.dtype size changed, may indicate binary incompatibility. Expected 96, got 88\n",
      "  from . import _hausdorff\n",
      "/usr/local/lib/python2.7/dist-packages/scipy/ndimage/measurements.py:36: RuntimeWarning: numpy.dtype size changed, may indicate binary incompatibility. Expected 96, got 88\n",
      "  from . import _ni_label\n",
      "/usr/local/lib/python2.7/dist-packages/scipy/signal/_max_len_seq.py:8: RuntimeWarning: numpy.dtype size changed, may indicate binary incompatibility. Expected 96, got 88\n",
      "  from ._max_len_seq_inner import _max_len_seq_inner\n",
      "/usr/local/lib/python2.7/dist-packages/scipy/signal/_upfirdn.py:36: RuntimeWarning: numpy.dtype size changed, may indicate binary incompatibility. Expected 96, got 88\n",
      "  from ._upfirdn_apply import _output_len, _apply\n",
      "/usr/local/lib/python2.7/dist-packages/scipy/optimize/_trlib/__init__.py:1: RuntimeWarning: numpy.dtype size changed, may indicate binary incompatibility. Expected 96, got 88\n",
      "  from ._trlib import TRLIBQuadraticSubproblem\n",
      "/usr/local/lib/python2.7/dist-packages/scipy/optimize/_numdiff.py:10: RuntimeWarning: numpy.dtype size changed, may indicate binary incompatibility. Expected 96, got 88\n",
      "  from ._group_columns import group_dense, group_sparse\n",
      "/usr/local/lib/python2.7/dist-packages/scipy/signal/spectral.py:10: RuntimeWarning: numpy.dtype size changed, may indicate binary incompatibility. Expected 96, got 88\n",
      "  from ._spectral import _lombscargle\n",
      "/usr/local/lib/python2.7/dist-packages/scipy/stats/_continuous_distns.py:18: RuntimeWarning: numpy.dtype size changed, may indicate binary incompatibility. Expected 96, got 88\n",
      "  from . import _stats\n",
      "/usr/local/lib/python2.7/dist-packages/scipy/signal/_peak_finding.py:13: RuntimeWarning: numpy.dtype size changed, may indicate binary incompatibility. Expected 96, got 88\n",
      "  from ._peak_finding_utils import (_argmaxima1d, _select_by_peak_distance,\n"
     ]
    },
    {
     "ename": "IOError",
     "evalue": "[Errno 2] No such file or directory: 'credentials.json'",
     "output_type": "error",
     "traceback": [
      "\u001b[0;31m\u001b[0m",
      "\u001b[0;31mIOError\u001b[0mTraceback (most recent call last)",
      "\u001b[0;32m/root/thomas/github/cloud_data_service/src/tasks.py\u001b[0m in \u001b[0;36m<module>\u001b[0;34m()\u001b[0m\n\u001b[1;32m     71\u001b[0m \u001b[0;34m\u001b[0m\u001b[0m\n\u001b[1;32m     72\u001b[0m \u001b[0;34m\u001b[0m\u001b[0m\n\u001b[0;32m---> 73\u001b[0;31m \u001b[0mcredentials\u001b[0m \u001b[0;34m=\u001b[0m \u001b[0mjson\u001b[0m\u001b[0;34m.\u001b[0m\u001b[0mload\u001b[0m\u001b[0;34m(\u001b[0m\u001b[0mopen\u001b[0m\u001b[0;34m(\u001b[0m\u001b[0;34m\"credentials.json\"\u001b[0m\u001b[0;34m)\u001b[0m\u001b[0;34m)\u001b[0m\u001b[0;34m\u001b[0m\u001b[0m\n\u001b[0m\u001b[1;32m     74\u001b[0m s3_client = boto3.client('s3', aws_access_key_id=credentials[\"aws_access_key_id\"],\n\u001b[1;32m     75\u001b[0m                          \u001b[0maws_secret_access_key\u001b[0m\u001b[0;34m=\u001b[0m\u001b[0mcredentials\u001b[0m\u001b[0;34m[\u001b[0m\u001b[0;34m\"aws_secret_access_key\"\u001b[0m\u001b[0;34m]\u001b[0m\u001b[0;34m,\u001b[0m\u001b[0;34m\u001b[0m\u001b[0m\n",
      "\u001b[0;31mIOError\u001b[0m: [Errno 2] No such file or directory: 'credentials.json'"
     ]
    }
   ],
   "source": [
    "%run -i 'tasks.py'"
   ]
  },
  {
   "cell_type": "code",
   "execution_count": null,
   "metadata": {},
   "outputs": [],
   "source": []
  }
 ],
 "metadata": {
  "kernelspec": {
   "display_name": "Python 2",
   "language": "python",
   "name": "python2"
  },
  "language_info": {
   "codemirror_mode": {
    "name": "ipython",
    "version": 2
   },
   "file_extension": ".py",
   "mimetype": "text/x-python",
   "name": "python",
   "nbconvert_exporter": "python",
   "pygments_lexer": "ipython2",
   "version": "2.7.12"
  }
 },
 "nbformat": 4,
 "nbformat_minor": 2
}
